<mujoco>
    <include file="piper_dependencies.xml"/>

    <worldbody>
        <light castshadow="false" directional='true' diffuse='.3 .3 .3' specular='0.3 0.3 0.3' pos='-1 -1 1' dir='1 1 -1'/>
        <light directional='true' diffuse='.3 .3 .3' specular='0.3 0.3 0.3' pos='1 -1 1' dir='-1 1 -1'/>
        <light castshadow="false" directional='true' diffuse='.3 .3 .3' specular='0.3 0.3 0.3' pos='0 1 1' dir='0 -1 -1'/>
        <!-- 地面 -->
        <geom name="floor" type="plane" size="10 10 0.1" rgba="0.8 0.8 0.8 1" friction="1 0.005 0.0005" condim="4"/>

        <body name="base_mocap" mocap="true" pos="0 0 0.08">
            <site name="base_mocap_site" size="0.01"/>
        </body>

        <body name="mobile_base" pos="0 0 0.3">
            <joint name="base_x"   type="slide" axis="1 0 0" damping="50"/>
            <joint name="base_y"   type="slide" axis="0 1 0" damping="50"/>
            <joint name="base_yaw" type="hinge" axis="0 0 1" damping="20"/>

            <geom name="chassis" type="box" size="0.35 0.25 0.05" mass="20"/>

            <!-- <body name="shape" pos="0.0 0.0 0.0">
                <geom name="shape" type="sphere" size="0.5" rgba="0 1 0 0.1" mass="10" contype="0" conaffinity="0" condim="4" solimp="0.9 0.95 0.001" solref="0.02 1"/>
            </body> -->

            <body name="lidar_base" pos="0 0 0.06">
                <site name="lidar_site" size="0.005" rgba="1 0 0 1"/>
            </body>

            <camera name="top" pos="0.26 0 1.24" euler="0 -0.785 -1.5708" fovy="120"/>

            <body name="left_mount" pos="0.26 0.28 0.57">
                <include file="piper_left_origin.xml"/>
            </body>
            <body name="right_mount" pos="0.26 -0.28 0.57">
                <include file="piper_right_origin.xml"/>
            </body>
            <body name="left_support" pos="0.26 0.28 0.26">
                <geom name="left_support" type="box" size="0.05 0.05 0.31" mass="0.1" />
            </body>
            <body name="right_support" pos="0.26 -0.28 0.26">
                <geom name="right_support" type="box" size="0.05 0.05 0.31" mass="0.1" />
            </body>
        </body>

        <body name="box" pos="1 1 1.02" euler="0 1.5708 0">
            <joint name="red_box_joint" type="free" frictionloss="0.01" />
            <inertial pos="0 0 0" mass="0.01" diaginertia="0.002 0.002 0.002" />
            <geom condim="4" solimp="2 1 0.01" solref="0.01 1" friction="1 1 0.0001" pos="0 0 0" size="0.02 0.02 0.02" type="box" name="red_box" rgba="1 0 0 1" />
        </body>

        <!-- Pick target column -->
        <body name="pick_target" pos="1 1 0.5">
            <geom name="pick_target_column" type="cylinder" size="0.05 0.5" rgba="0 0 1 1" mass="10" contype="1" conaffinity="1" condim="4" solimp="0.9 0.95 0.001" solref="0.02 1"/>
        </body>

        <!-- Place target column -->
        <body name="place_target" pos="1 -1 0.5">
            <geom name="place_target_column" type="cylinder" size="0.05 0.5" rgba="0 0 1 1" mass="10" contype="1" conaffinity="1" condim="4" solimp="0.9 0.95 0.001" solref="0.02 1"/>
        </body>

        <!-- U-shape Obstacle Map -->
        <body name="behind_wall_1" pos="-1.5 -2.5 0.3">
            <geom name="behind_wall_1" type="sphere" size="0.3" rgba="0 1 0 1" mass="10" contype="1" conaffinity="1" condim="4" solimp="0.9 0.95 0.001" solref="0.02 1"/>
        </body>
        <body name="behind_wall_2" pos="-1.5 -2.0 0.3">
            <geom name="behind_wall_2" type="sphere" size="0.3" rgba="0 1 0 1" mass="10" contype="1" conaffinity="1" condim="4" solimp="0.9 0.95 0.001" solref="0.02 1"/>
        </body>
        <body name="behind_wall_3" pos="-1.5 -1.5 0.3">
            <geom name="behind_wall_3" type="sphere" size="0.3" rgba="0 1 0 1" mass="10" contype="1" conaffinity="1" condim="4" solimp="0.9 0.95 0.001" solref="0.02 1"/>
        </body>
        <body name="behind_wall_4" pos="-1.5 -1.0 0.3">
            <geom name="behind_wall_4" type="sphere" size="0.3" rgba="0 1 0 1" mass="10" contype="1" conaffinity="1" condim="4" solimp="0.9 0.95 0.001" solref="0.02 1"/>
        </body>
        <body name="behind_wall_5" pos="-1.5 -0.5 0.3">
            <geom name="behind_wall_5" type="sphere" size="0.3" rgba="0 1 0 1" mass="10" contype="1" conaffinity="1" condim="4" solimp="0.9 0.95 0.001" solref="0.02 1"/>
        </body>
        <body name="behind_wall_6" pos="-1.5 0.0 0.3">
            <geom name="behind_wall_6" type="sphere" size="0.3" rgba="0 1 0 1" mass="10" contype="1" conaffinity="1" condim="4" solimp="0.9 0.95 0.001" solref="0.02 1"/>
        </body>
        <body name="behind_wall_7" pos="-1.5 0.5 0.3">
            <geom name="behind_wall_7" type="sphere" size="0.3" rgba="0 1 0 1" mass="10" contype="1" conaffinity="1" condim="4" solimp="0.9 0.95 0.001" solref="0.02 1"/>
        </body>
        <body name="behind_wall_8" pos="-1.5 1.0 0.3">
            <geom name="behind_wall_8" type="sphere" size="0.3" rgba="0 1 0 1" mass="10" contype="1" conaffinity="1" condim="4" solimp="0.9 0.95 0.001" solref="0.02 1"/>
        </body>
        <body name="behind_wall_9" pos="-1.5 1.5 0.3">
            <geom name="behind_wall_9" type="sphere" size="0.3" rgba="0 1 0 1" mass="10" contype="1" conaffinity="1" condim="4" solimp="0.9 0.95 0.001" solref="0.02 1"/>
        </body>
        <body name="behind_wall_10" pos="-1.5 2.0 0.3">
            <geom name="behind_wall_10" type="sphere" size="0.3" rgba="0 1 0 1" mass="10" contype="1" conaffinity="1" condim="4" solimp="0.9 0.95 0.001" solref="0.02 1"/>
        </body>
        <body name="behind_wall_11" pos="-1.5 2.5 0.3">
            <geom name="behind_wall_11" type="sphere" size="0.3" rgba="0 1 0 1" mass="10" contype="1" conaffinity="1" condim="4" solimp="0.9 0.95 0.001" solref="0.02 1"/>
        </body>

        <!-- Right vertical wall -->
        <body name="right_wall_1" pos="-1.5 -2.5 0.3">
            <geom name="right_wall_1" type="sphere" size="0.3" rgba="0 1 0 1" mass="10" contype="1" conaffinity="1" condim="4" solimp="0.9 0.95 0.001" solref="0.02 1"/>
        </body>
        <body name="right_wall_2" pos="-1.0 -2.5 0.3">
            <geom name="right_wall_2" type="sphere" size="0.3" rgba="0 1 0 1" mass="10" contype="1" conaffinity="1" condim="4" solimp="0.9 0.95 0.001" solref="0.02 1"/>
        </body>
        <body name="right_wall_3" pos="-0.5 -2.5 0.3">
            <geom name="right_wall_3" type="sphere" size="0.3" rgba="0 1 0 1" mass="10" contype="1" conaffinity="1" condim="4" solimp="0.9 0.95 0.001" solref="0.02 1"/>
        </body>
        <body name="right_wall_4" pos="0.0 -2.5 0.3">
            <geom name="right_wall_4" type="sphere" size="0.3" rgba="0 1 0 1" mass="10" contype="1" conaffinity="1" condim="4" solimp="0.9 0.95 0.001" solref="0.02 1"/>
        </body>
        <body name="right_wall_5" pos="0.5 -2.5 0.3">
            <geom name="right_wall_5" type="sphere" size="0.3" rgba="0 1 0 1" mass="10" contype="1" conaffinity="1" condim="4" solimp="0.9 0.95 0.001" solref="0.02 1"/>
        </body>
        <body name="right_wall_6" pos="1.0 -2.5 0.3">
            <geom name="right_wall_6" type="sphere" size="0.3" rgba="0 1 0 1" mass="10" contype="1" conaffinity="1" condim="4" solimp="0.9 0.95 0.001" solref="0.02 1"/>
        </body>
        <body name="right_wall_7" pos="1.5 -2.5 0.3">
            <geom name="right_wall_7" type="sphere" size="0.3" rgba="0 1 0 1" mass="10" contype="1" conaffinity="1" condim="4" solimp="0.9 0.95 0.001" solref="0.02 1"/>
        </body>

        <!-- Front horizontal wall -->
        <body name="front_wall_1" pos="1.5 -2.5 0.3">
            <geom name="front_wall_1" type="sphere" size="0.3" rgba="0 1 0 1" mass="10" contype="1" conaffinity="1" condim="4" solimp="0.9 0.95 0.001" solref="0.02 1"/>
        </body>
        <body name="front_wall_2" pos="1.5 -2.0 0.3">
            <geom name="front_wall_2" type="sphere" size="0.3" rgba="0 1 0 1" mass="10" contype="1" conaffinity="1" condim="4" solimp="0.9 0.95 0.001" solref="0.02 1"/>
        </body>
        <body name="front_wall_3" pos="1.5 -1.5 0.3">
            <geom name="front_wall_3" type="sphere" size="0.3" rgba="0 1 0 1" mass="10" contype="1" conaffinity="1" condim="4" solimp="0.9 0.95 0.001" solref="0.02 1"/>
        </body>
        <body name="front_wall_4" pos="1.5 -1.0 0.3">
            <geom name="front_wall_4" type="sphere" size="0.3" rgba="0 1 0 1" mass="10" contype="1" conaffinity="1" condim="4" solimp="0.9 0.95 0.001" solref="0.02 1"/>
        </body>
        <body name="front_wall_5" pos="1.5 -0.5 0.3">
            <geom name="front_wall_5" type="sphere" size="0.3" rgba="0 1 0 1" mass="10" contype="1" conaffinity="1" condim="4" solimp="0.9 0.95 0.001" solref="0.02 1"/>
        </body>
        <body name="front_wall_6" pos="1.5 0.0 0.3">
            <geom name="front_wall_6" type="sphere" size="0.3" rgba="0 1 0 1" mass="10" contype="1" conaffinity="1" condim="4" solimp="0.9 0.95 0.001" solref="0.02 1"/>
        </body>
        <body name="front_wall_7" pos="1.5 0.5 0.3">
            <geom name="front_wall_7" type="sphere" size="0.3" rgba="0 1 0 1" mass="10" contype="1" conaffinity="1" condim="4" solimp="0.9 0.95 0.001" solref="0.02 1"/>
        </body>
        <body name="front_wall_8" pos="1.5 1.0 0.3">
            <geom name="front_wall_8" type="sphere" size="0.3" rgba="0 1 0 1" mass="10" contype="1" conaffinity="1" condim="4" solimp="0.9 0.95 0.001" solref="0.02 1"/>
        </body>
        <body name="front_wall_9" pos="1.5 1.5 0.3">
            <geom name="front_wall_9" type="sphere" size="0.3" rgba="0 1 0 1" mass="10" contype="1" conaffinity="1" condim="4" solimp="0.9 0.95 0.001" solref="0.02 1"/>
        </body>
        <body name="front_wall_10" pos="1.5 2.0 0.3">
            <geom name="front_wall_10" type="sphere" size="0.3" rgba="0 1 0 1" mass="10" contype="1" conaffinity="1" condim="4" solimp="0.9 0.95 0.001" solref="0.02 1"/>
        </body>
        <body name="front_wall_11" pos="1.5 2.5 0.3">
            <geom name="front_wall_11" type="sphere" size="0.3" rgba="0 1 0 1" mass="10" contype="1" conaffinity="1" condim="4" solimp="0.9 0.95 0.001" solref="0.02 1"/>
        </body>

        <!-- Left vertical wall -->
        <body name="left_wall_1" pos="-1.5 2.5 0.3">
            <geom name="left_wall_1" type="sphere" size="0.3" rgba="0 1 0 1" mass="10" contype="1" conaffinity="1" condim="4" solimp="0.9 0.95 0.001" solref="0.02 1"/>
        </body>
        <body name="left_wall_2" pos="-1.0 2.5 0.3">
            <geom name="left_wall_2" type="sphere" size="0.3" rgba="0 1 0 1" mass="10" contype="1" conaffinity="1" condim="4" solimp="0.9 0.95 0.001" solref="0.02 1"/>
        </body>
        <body name="left_wall_3" pos="-0.5 2.5 0.3">
            <geom name="left_wall_3" type="sphere" size="0.3" rgba="0 1 0 1" mass="10" contype="1" conaffinity="1" condim="4" solimp="0.9 0.95 0.001" solref="0.02 1"/>
        </body>
        <body name="left_wall_4" pos="0.0 2.5 0.3">
            <geom name="left_wall_4" type="sphere" size="0.3" rgba="0 1 0 1" mass="10" contype="1" conaffinity="1" condim="4" solimp="0.9 0.95 0.001" solref="0.02 1"/>
        </body>
        <body name="left_wall_5" pos="0.5 2.5 0.3">
            <geom name="left_wall_5" type="sphere" size="0.3" rgba="0 1 0 1" mass="10" contype="1" conaffinity="1" condim="4" solimp="0.9 0.95 0.001" solref="0.02 1"/>
        </body>
        <body name="left_wall_6" pos="1.0 2.5 0.3">
            <geom name="left_wall_6" type="sphere" size="0.3" rgba="0 1 0 1" mass="10" contype="1" conaffinity="1" condim="4" solimp="0.9 0.95 0.001" solref="0.02 1"/>
        </body>
        <body name="left_wall_7" pos="1.5 2.5 0.3">
            <geom name="left_wall_7" type="sphere" size="0.3" rgba="0 1 0 1" mass="10" contype="1" conaffinity="1" condim="4" solimp="0.9 0.95 0.001" solref="0.02 1"/>
        </body>

        <!-- Middle vertical wall -->
        <body name="middle_wall_1" pos="1.0 0.0 0.3">
            <geom name="middle_wall_1" type="sphere" size="0.1" rgba="0 1 0 1" mass="10" contype="1" conaffinity="1" condim="4" solimp="0.9 0.95 0.001" solref="0.02 1"/>
        </body>
        <body name="middle_wall_2" pos="0.5 0.0 0.3">
            <geom name="middle_wall_2" type="sphere" size="0.1" rgba="0 1 0 1" mass="10" contype="1" conaffinity="1" condim="4" solimp="0.9 0.95 0.001" solref="0.02 1"/>
        </body>
        <body name="middle_wall_3" pos="0.0 0.0 0.3">
            <geom name="middle_wall_3" type="sphere" size="0.1" rgba="0 1 0 1" mass="10" contype="1" conaffinity="1" condim="4" solimp="0.9 0.95 0.001" solref="0.02 1"/>
        </body>

    </worldbody>

    <equality>
        <weld name="weld_base_to_mocap" body1="base_mocap" body2="mobile_base" solref="0.0001 1" solimp="0.9 0.95 0.0001"/>
    </equality>

    <actuator>
        <position ctrllimited="true" ctrlrange="-2.618 2.618" joint="piper_left/joint1" kp="800"  user="1" forcelimited="true" forcerange="-150 150"/>
        <position ctrllimited="true" ctrlrange="0 3.14" joint="piper_left/joint2" kp="1600"  user="1" forcelimited="true" forcerange="-300 300"/>
        <position ctrllimited="true" ctrlrange="-2.967 0" joint="piper_left/joint3" kp="800"  user="1" forcelimited="true" forcerange="-100 100"/>
        <position ctrllimited="true" ctrlrange="-1.745 1.745" joint="piper_left/joint4" kp="100"  user="1" forcelimited="true" forcerange="-100 100"/>
        <position ctrllimited="true" ctrlrange="-1.22 1.22" joint="piper_left/joint5" kp="500"  user="1"/>
        <position ctrllimited="true" ctrlrange="-2.0944 2.0944" joint="piper_left/joint6" kp="200"  user="1"/>
        <position ctrllimited="true" ctrlrange="0 0.035" joint="piper_left/joint7" kp="1000"  user="1"/>
        <position ctrllimited="true" ctrlrange="-0.035 0" joint="piper_left/joint8" kp="1000"  user="1"/>

        <position ctrllimited="true" ctrlrange="-2.618 2.618" joint="piper_right/joint1" kp="800"  user="1" forcelimited="true" forcerange="-150 150"/>
        <position ctrllimited="true" ctrlrange="0 3.14" joint="piper_right/joint2" kp="1600"  user="1" forcelimited="true" forcerange="-300 300"/>
        <position ctrllimited="true" ctrlrange="-2.967 0" joint="piper_right/joint3" kp="800"  user="1" forcelimited="true" forcerange="-100 100"/>
        <position ctrllimited="true" ctrlrange="-1.745 1.745" joint="piper_right/joint4" kp="100"  user="1" forcelimited="true" forcerange="-100 100"/>
        <position ctrllimited="true" ctrlrange="-1.22 1.22" joint="piper_right/joint5" kp="500"  user="1"/>
        <position ctrllimited="true" ctrlrange="-2.0944 2.0944" joint="piper_right/joint6" kp="200"  user="1"/>
        <position ctrllimited="true" ctrlrange="0 0.035" joint="piper_right/joint7" kp="1000" user="1"/>
        <position ctrllimited="true" ctrlrange="-0.035 0" joint="piper_right/joint8" kp="1000" user="1"/>
    </actuator>
</mujoco>
